Workbook
Name For: 'Ficha Pessoal'!$D$10
Name Sab: 'Ficha Pessoal'!$H$14
Name BT: 'Ficha Pessoal'!$BH$3
Name Int: 'Ficha Pessoal'!$D$14
Name Des: 'Ficha Pessoal'!$H$10
Name Pre: 'Ficha Pessoal'!$L$14
Name Con: 'Ficha Pessoal'!$L$10

Sheet Calculos
C1: Lutador | D1: Esp em C | E1: Esp em T | F1: Suporte | G1: Controlador | H1: Restringido
C2: ='Ficha Pessoal'!L10+12+IF('Ficha Pessoal'!BD3 > 1,(6+'Ficha Pessoal'!L10)*('Ficha Pessoal'!BD3-1), +0) -> 46 | D2: ='Ficha Pessoal'!L10+12+IF('Ficha Pessoal'!BD3 > 1,(6+'Ficha Pessoal'!L10)*('Ficha Pessoal'!BD3-1), +0) -> 46 | E2: ='Ficha Pessoal'!L10+10+IF('Ficha Pessoal'!BD3 > 1,(5+'Ficha Pessoal'!L10)*('Ficha Pessoal'!BD3-1), +0) -> 40 | F2: =IF(F4 >= 1, MAX(Pre,Sab)+10, 'Ficha Pessoal'!L10+10)+IF('Ficha Pessoal'!BD3 > 1, IF(F4 >= 1, (MAX(Pre,Sab)+5)*('Ficha Pessoal'!BD3-1), (5+'Ficha Pessoal'!L10)*('Ficha Pessoal'!BD3-1)), +0) -> 40 | G2: ='Ficha Pessoal'!L10+10+IF('Ficha Pessoal'!BD3 > 1,(5+'Ficha Pessoal'!L10)*('Ficha Pessoal'!BD3-1), +0) -> 40 | H2: ='Ficha Pessoal'!L10+16+IF('Ficha Pessoal'!BD3 > 1,(7+'Ficha Pessoal'!L10)*('Ficha Pessoal'!BD3-1), +0) -> 54
F4: =COUNTIF('Ficha Pessoal'!BH9:BM35, "Físico Controlado")+COUNTIF('Ficha Pessoal'!BH9:BM35, "Fisico Controlado") -> 0

Sheet Ficha Pessoal
B2: FEITICEIROS & MALDIÇÕES | O2: NOME | S2: Oliver Pendragon | AC2: ORIGEM | AH2: herdado (clã Pendragon) | AP2: CAMPANHA | BD2: Nível | BG2: 6 | BH2: Treinamento | BK2: Lembre-se de utilizar a função de Notas para anotar o funcionamento de suas habilidades, talentos e outros.
AC3: ESPECIALIZAÇÃO | AH3: Controlador | AP3: GRAU | BD3: 5 | BH3: =Int(SUM(1+ROUNDUP(BD3/4,0))) -> 3
C4: FICHA DE PERSONAGEM v2.5 | O4: JOGADOR | S4: Eric | AC4: TÉCNICA | AH4: Heragon | AP4: EXPERIÊNCIA
B6: ATRIBUTOS | O6: PONTOS DE VIDA | X6: EXTRA | AC6: PONTOS DE ENERGIA | AM6: INTEGRIDADE | AZ6: DEFESA | BH6: HABILIDADES E TALENTOS
O7: ATUAIS | R7: PERDIDOS | U7: MÁXIMOS | X7: KAMO | AA7: FALSE | AC7: ATUAIS | AF7: PERDIDOS | AI7: MÁXIMOS | AM7: ATUAL | AP7: PERDIDOS | AS7: MÁXIMA | AV7: ESTADO ATUAL | AZ7: Total | BC7: Base | BE7: 10
B8: FORÇA | F8: DESTREZA | J8: CONSTITUIÇÃO | O8: =U8-R8 -> 6 | R8: 34 | U8: =AM8 -> 40 | X8: ROBUSTEZ | AA8: FALSE | AC8: 33 | AF8: 18 | AI8: 33 | AM8: =AS8-AP8 -> 40 | AS8: =IFS(AH3 = "Lutador", Calculos!C2, AH3 = "Especialista em Combate", Calculos!D2, AH3 = "Especialista em Técnica", Calculos!E2, AH3 = "Suporte", Calculos!F2, AH3 = "Controlador", Calculos!G2,AH3 = "Restringido", Calculos!H2, TRUE, 0) +IF(AA7 = TRUE, IF(BD3 >= 10, Con+(1*BD3), 1*BD3), +0) +IF(AA8 = TRUE, 1*BD3, 0) +IF(AA9 = TRUE, 1*BD3, 0) +IF(AA10 = TRUE, 1*BD3, 0) +Z11 +IF(Treinamentos!AS17 = TRUE, 4, 0) +IF(Treinamentos!AS20 = TRUE, 16, 0) -> 40 | AZ8: =BE7+BE8+BE9+BE10+BE11+IF(Treinamentos!I18 = TRUE, +2, +0) -> 18 | BC8: Equip. | BH8: Nome | BN8: Atual | BP8: Máx. | BR8: Custo
B9: Valor | D9: Mod. | F9: Valor | H9: Mod. | J9: Valor | L9: Mod. | X9: DES. EXA. | AA9: FALSE | AV9: =IFS(AM8<=0, "Morto", AM8<=AS8*0.25, "Crítico", AM8<=AS8*0.5, "Instável", AM8<=AS8*0.75, "Danificado", TRUE, "Estavel") -> Estavel | BC9: Destreza | BE9: =Des -> 2 | BH9: Treinamento em Controle.
B10: 8 | D10: =IF(B10>=10,ROUNDDOWN((B10-10)/2,0),ROUNDUP((B10-10)/2,0)) -> -1 | F10: 14 | H10: =IF(F10>=10,ROUNDDOWN((F10-10)/2,0),ROUNDUP((F10-10)/2,0)) -> 2 | J10: 14 | L10: =IF(J10>=10,ROUNDDOWN((J10-10)/2,0),ROUNDUP((J10-10)/2,0)) -> 2 | X10: VIGOR INF. | AA10: FALSE | AV10: RD | BC10: Nível/2 | BE10: =ROUNDDOWN(BD3/2,0) -> 2 | BH10: TÉCNICAS DE COMBATE
X11: Outros | AV11: 0 | BC11: Outros | BE11: 4 | BH11: INVOCAÇÕES RESISTENTES
B12: INTELIGÊNCIA | F12: SABEDORIA | J12: PRESENÇA | BH12: Controle Aprimorado.
B13: Valor | D13: Mod. | F13: Valor | H13: Mod. | J13: Valor | L13: Mod. | O13: JOGADAS DE ATAQUE | Y13: TESTES DE RESISTÊNCIA | AO13: Desloc. | AS13: CD Especialização | AZ13: TESTES DE MORTE | BH13: AUTONOMIA
B14: 12 | D14: =IF(B14>=10,ROUNDDOWN((B14-10)/2,0),ROUNDUP((B14-10)/2,0)) -> 1 | F14: 10 | H14: =IF(F14>=10,ROUNDDOWN((F14-10)/2,0),ROUNDUP((F14-10)/2,0)) -> 0 | J14: 19 | L14: =IF(J14>=10,ROUNDDOWN((J14-10)/2,0),ROUNDUP((J14-10)/2,0)) -> 4 | O14: Corpo a Corpo | R14: A Distância | U14: Amaldiçoado | Y14: Astúcia | AB14: Fortitude | AE14: Integridade | AH14: Reflexos | AK14: Vontade | AO14: 9 | AS14: Total | AV14: Base | AX14: 10 | BH14: POTENCIAL SUPERIOR
O15: =P18+ROUNDDOWN(BD3/2,0)+ROUNDDOWN(IF(O20="FOR",For,Des)+IF(O18,BT,0),0) -> 1 | R15: =S18+ROUNDDOWN(BD3/2,0)+ROUNDDOWN(IF(R20="FOR",For,Des)+IF(R18,BT,0),0) -> 4 | U15: =V18+ROUNDDOWN(BD3/2,0)+ROUNDDOWN(IFS(U20="FOR",For, U20="DES",Des, U20="Int",Int, U20="SAB",Sab, U20="Con", Con, U20="PRE", Pre)+IF(U18,BT,0),0) -> 6 | Y15: =AA18+ROUNDDOWN(BD3/2,0)+ROUNDDOWN(IF(Z18,Int+BT*1.5,IF(Y18,Int+BT,Int)),0) -> 3 | AB15: =AD18+ROUNDDOWN(BD3/2,0)+ROUNDDOWN(IF(AC18,Con+BT*1.5,IF(AB18,Con+BT,Con)),0)+IF(Treinamentos!AS19 = TRUE, +2, +0)+IF(AA8 = TRUE, +2, +0) -> 4 | AE15: =AG18+ROUNDDOWN(BD3/2,0)+ROUNDDOWN(IF(AF18,Con+BT*1.5,IF(AE18,Con+BT,Con)),0) -> 4 | AH15: =AJ18+ROUNDDOWN(BD3/2,0)+ROUNDDOWN(IF(AI18,Des+BT*1.5,IF(AH18,Des+BT,Des)),0)+IF(Treinamentos!I8 = TRUE, +2, +0) -> 4 | AK15: =AM18+ROUNDDOWN(BD3/2,0)+ROUNDDOWN(IF(AL18,Sab+BT*1.5,IF(AK18,Sab+BT,Sab)),0) -> 5 | AS15: =AX14+SWITCH(AX15, "F", For, "D", Des, "C", Con, "I", Int, "S", Sab, "P", Pre, 0)+AX16+AX17+AX18 -> 19 | AV15: Atributo | AX15: P | AZ15: Sucessos | BD15: FALSE | BE15: FALSE | BF15: FALSE
AV16: Treino | AX16: =BH3 -> 3 | AZ16: Falhas | BD16: FALSE | BE16: FALSE | BF16: FALSE
B17: ATENÇÃO | H17: INICIATIVA | O17: T | P17: Outros | R17: T | S17: Outros | U17: T | V17: Outros | Y17: T | Z17: M | AA17: O | AB17: T | AC17: M | AD17: O | AE17: T | AF17: M | AG17: O | AH17: T | AI17: M | AJ17: O | AK17: T | AL17: M | AM17: O | AV17: Nível/2 | AX17: =ROUNDDOWN(BD3/2,0) -> 2
B18: Total | E18: Base | G18: 10 | H18: Total | O18: FALSE | R18: FALSE | U18: FALSE | Y18: FALSE | Z18: FALSE | AB18: FALSE | AC18: FALSE | AE18: FALSE | AF18: FALSE | AH18: FALSE | AI18: FALSE | AK18: TRUE | AL18: FALSE | AV18: Outros | AZ18: DADOS DE VIDA
B19: =G18+G19+G20 -> 15 | E19: Percep. | G19: =X30 -> 5 | H19: =M19+M20+IF(Treinamentos!I7 = TRUE, +2, +0) -> 2 | K19: Destreza | M19: =Des -> 2 | O19: Atributo | R19: Atributo | U19: Atributo
E20: Outros | K20: Outros | O20: FOR | R20: DES | U20: PRE | AA20: RDs | AN20: RESISTENCIAS | AT20: TREINAMENTOS | AZ20: Dados | BB20: Gastos | BD20: Disponíveis
AA21: COR | AB21: IMP | AC21: PER | AD21: CON | AE21: QUE | AF21: CHO | AG21: SON | AH21: ENE | AI21: PSI | AJ21: RAD | AK21: NEC | AL21: VEN | AT21: armas simples e armas a distancia | AZ21: d8
B22: PERÍCIAS | AZ22: d10
AZ23: d12
B24: Perícia | F24: Atributo | H24: Outros | J24: T | K24: M | L24: Total | N24: Perícia | R24: Atributo | T24: Outros | V24: T | W24: M | X24: Total
B25: Atletismo | F25: FOR | J25: FALSE | K25: FALSE | L25: =H25+ROUNDDOWN(BD3/2,0)+ROUNDDOWN(IF(K25,For+BT*1.5,IF(J25,For+BT,For)),0) -> 1 | N25: Teologia | R25: INT | V25: FALSE | W25: FALSE | X25: =T25+ROUNDDOWN(BD3/2,0)+ROUNDDOWN(IF(W25,Int+BT*1.5,IF(V25,Int+BT,Int)),0) -> 3 | AA25: ATAQUES | AZ25: CARACTERÍSTICAS
B26: Acrobacia | F26: DES | J26: TRUE | K26: FALSE | L26: =H26+ROUNDDOWN(BD3/2,0)+ROUNDDOWN(IF(K26,Des+BT*1.5,IF(J26,Des+BT,Des)),0)+IF(Treinamentos!I6 = TRUE, +2, +0) -> 7 | N26: Direção | R26: SAB | V26: FALSE | W26: FALSE | X26: =T26+ROUNDDOWN(BD3/2,0)+ROUNDDOWN(IF(W26,Sab+BT*1.5,IF(V26,Sab+BT,Sab)),0) -> 2 | AA26: ARMA | AF26: BÔNUS | AH26: DANO | AL26: CRÍT. | AN26: TIPO | AQ26: ALCANCE | AT26: PROPRIEDADES
B27: Furtividade | F27: DES | J27: FALSE | K27: FALSE | L27: =H27+ROUNDDOWN(BD3/2,0)+ROUNDDOWN(IF(K27,Des+BT*1.5,IF(J27,Des+BT,Des)),0) -> 4 | N27: Intuição | R27: SAB | V27: FALSE | W27: FALSE | X27: =T27+ROUNDDOWN(BD3/2,0)+ROUNDDOWN(IF(W27,Sab+BT*1.5,IF(V27,Sab+BT,Sab)),0) -> 2 | AA27: espada longa | AF27: 11 | AH27: 1d8+11/1d10+11 | AL27: 20 | AN27: cortante
B28: Prestidigitação | F28: DES | J28: FALSE | K28: FALSE | L28: =H28+ROUNDDOWN(BD3/2,0)+ROUNDDOWN(IF(K28,Des+BT*1.5,IF(J28,Des+BT,Des)),0) -> 4 | N28: Medicina | R28: SAB | V28: FALSE | W28: FALSE | X28: =T28+ROUNDDOWN(BD3/2,0)+ROUNDDOWN(IF(W28,Sab+BT*1.5,IF(V28,Sab+BT,Sab)),0) -> 2
B29: Feitiçaria | F29: INT | J29: TRUE | K29: FALSE | L29: =H29+ROUNDDOWN(BD3/2,0)+ROUNDDOWN(IF(K29,Int+BT*1.5,IF(J29,Int+BT,Int)),0)+IF(Treinamentos!AA6 = TRUE, +1, +0)+IF(Treinamentos!AA8 = TRUE, +2, +0) -> 6 | N29: Ocultismo | R29: SAB | V29: FALSE | W29: FALSE | X29: =T29+ROUNDDOWN(BD3/2,0)+ROUNDDOWN(IF(W29,Sab+BT*1.5,IF(V29,Sab+BT,Sab)),0)+IF(Treinamentos!AA6 = TRUE, +1, +0)+IF(Treinamentos!AA8 = TRUE, +2, +0) -> 2
B30: História | F30: INT | J30: TRUE | K30: TRUE | L30: =H30+ROUNDDOWN(BD3/2,0)+ROUNDDOWN(IF(K30,Int+BT*1.5,IF(J30,Int+BT,Int)),0) -> 7 | N30: Percepção | R30: SAB | V30: TRUE | W30: FALSE | X30: =T30+ROUNDDOWN(BD3/2,0)+ROUNDDOWN(IF(W30,Sab+BT*1.5,IF(V30,Sab+BT,Sab)),0) -> 5
B31: Investigação | F31: INT | J31: TRUE | K31: FALSE | L31: =H31+ROUNDDOWN(BD3/2,0)+ROUNDDOWN(IF(K31,Int+BT*1.5,IF(J31,Int+BT,Int)),0) -> 6 | N31: Sobrevivência | R31: SAB | V31: FALSE | W31: FALSE | X31: =T31+ROUNDDOWN(BD3/2,0)+ROUNDDOWN(IF(W31,Sab+BT*1.5,IF(V31,Sab+BT,Sab)),0) -> 2
B32: Ofício (__) | F32: INT | J32: FALSE | K32: FALSE | L32: =H32+ROUNDDOWN(BD3/2,0)+ROUNDDOWN(IF(K32,Int+BT*1.5,IF(J32,Int+BT,Int)),0) -> 3 | N32: Enganação | R32: PRE | V32: FALSE | W32: FALSE | X32: =T32+ROUNDDOWN(BD3/2,0)+ROUNDDOWN(IF(W32,Pre+BT*1.5,IF(V32,Pre+BT,Pre)),0) -> 6 | AA32: ANOTAÇÕES
B33: Ofício (__) | F33: INT | J33: FALSE | K33: FALSE | L33: =H33+ROUNDDOWN(BD3/2,0)+ROUNDDOWN(IF(K33,Int+BT*1.5,IF(J33,Int+BT,Int)),0) -> 3 | N33: Intimidação | R33: PRE | V33: FALSE | W33: FALSE | X33: =T33+ROUNDDOWN(BD3/2,0)+ROUNDDOWN(IF(W33,Pre+BT*1.5,IF(V33,Pre+BT,Pre)),0) -> 6
B34: Ofício (__) | F34: INT | J34: FALSE | K34: FALSE | L34: =H34+ROUNDDOWN(BD3/2,0)+ROUNDDOWN(IF(K34,Int+BT*1.5,IF(J34,Int+BT,Int)),0) -> 3 | N34: Performance | R34: PRE | V34: FALSE | W34: FALSE | X34: =T34+ROUNDDOWN(BD3/2,0)+ROUNDDOWN(IF(W34,Pre+BT*1.5,IF(V34,Pre+BT,Pre)),0) -> 6
B35: Tecnologia | F35: INT | J35: FALSE | K35: FALSE | L35: =H35+ROUNDDOWN(BD3/2,0)+ROUNDDOWN(IF(K35,Int+BT*1.5,IF(J35,Int+BT,Int)),0) -> 3 | N35: Persuasão | R35: PRE | V35: TRUE | W35: FALSE | X35: =T35+ROUNDDOWN(BD3/2,0)+ROUNDDOWN(IF(W35,Pre+BT*1.5,IF(V35,Pre+BT,Pre)),0) -> 9

Sheet Registro e Inventário
B2: REGISTRO E INVENTÁRIO
B5: APARÊNCIA | J5: NOME | N5: ='Ficha Pessoal'!S2 -> Oliver Pendragon | Y5: INVENTÁRIO
J7: IDADE | Y7: NOME DO ITEM | AG7: QUANT. | AI7: PESO | AK7: PREÇO | AN7: NOME DO ITEM | AV7: QUANT. | AX7: PESO | AZ7: PREÇO
J8: ALTURA | Y8: ferramentas ferreiro | BB8: =SUM(PRODUCT(AG8,AI8),PRODUCT(AV8,AX8)) -> 0
J9: PESO | Y9: Apanhador de Saúde [Acessório]. | BB9: =SUM(PRODUCT(AG9,AI9),PRODUCT(AV9,AX9)) -> 0
J10: GÊNERO | Y10: Espada longa | BB10: =SUM(PRODUCT(AG10,AI10),PRODUCT(AV10,AX10)) -> 0
J11: CABELOS | Y11: Pérola Carregada [Espiritual]. | BB11: =SUM(PRODUCT(AG11,AI11),PRODUCT(AV11,AX11)) -> 0
J12: OLHOS | Y12: Símbolo da Vida [Talismã]. | BB12: =SUM(PRODUCT(AG12,AI12),PRODUCT(AV12,AX12)) -> 0
J13: PELE | BB13: =SUM(PRODUCT(AG13,AI13),PRODUCT(AV13,AX13)) -> 0
J14: ROUPAS | BB14: =SUM(PRODUCT(AG14,AI14),PRODUCT(AV14,AX14)) -> 0
J15: MARCA | BB15: =SUM(PRODUCT(AG15,AI15),PRODUCT(AV15,AX15)) -> 0
B16: TRAÇOS DE PERSONALIDADE | BB16: =SUM(PRODUCT(AG16,AI16),PRODUCT(AV16,AX16)) -> 0
BB17: =SUM(PRODUCT(AG17,AI17),PRODUCT(AV17,AX17)) -> 0
BB18: =SUM(PRODUCT(AG18,AI18),PRODUCT(AV18,AX18)) -> 0
BB19: =SUM(PRODUCT(AG19,AI19),PRODUCT(AV19,AX19)) -> 0
B20: IDEAIS | BB20: =SUM(PRODUCT(AG20,AI20),PRODUCT(AV20,AX20)) -> 0
BB21: =SUM(PRODUCT(AG21,AI21),PRODUCT(AV21,AX21)) -> 0
BB22: =SUM(PRODUCT(AG22,AI22),PRODUCT(AV22,AX22)) -> 0
BB23: =SUM(PRODUCT(AG23,AI23),PRODUCT(AV23,AX23)) -> 0
B24: LIGAÇÕES | BB24: =SUM(PRODUCT(AG24,AI24),PRODUCT(AV24,AX24)) -> 0
BB25: =SUM(PRODUCT(AG25,AI25),PRODUCT(AV25,AX25)) -> 0
BB26: =SUM(PRODUCT(AG26,AI26),PRODUCT(AV26,AX26)) -> 0
BB27: =SUM(PRODUCT(AG27,AI27),PRODUCT(AV27,AX27)) -> 0
B28: COMPLICAÇÕES | BB28: =SUM(PRODUCT(AG28,AI28),PRODUCT(AV28,AX28)) -> 0
BB29: =SUM(PRODUCT(AG29,AI29),PRODUCT(AV29,AX29)) -> 0
BB30: =SUM(PRODUCT(AG30,AI30),PRODUCT(AV30,AX30)) -> 0
BB31: =SUM(PRODUCT(AG31,AI31),PRODUCT(AV31,AX31)) -> 0
B32: DOMÍNIO INATO | BB32: =SUM(PRODUCT(AG32,AI32),PRODUCT(AV32,AX32)) -> 0
Y34: Espaços Ocupados | AI34: =SUM(BB8:BB32) -> 0 | AN34: Limite de Espaços | AX34: =For*2+8 -> 6

Sheet Perfil Amaldiçoado
B2: PERFIL AMALDIÇOADO
B5: TÉCNICA AMALDIÇOADA | N5: APTIDÕES AMALDIÇOADAS | AA5: LISTA DE FEITIÇOS | BB5: EXPANSÃO DE DOMÍNIO
B7: NOME DA TÉCNICA | N7: Nome | T7: Atual | V7: Máx. | X7: Custo | AA7: FEITIÇOS NÍVEL 0 | AJ7: FEITIÇOS NÍVEL 1 | AS7: FEITIÇOS NÍVEL 2 | BB7: NOME DA EXPANSÃO
N8: TÉCNICAS DE BARREIRA | AJ8: embuir arma | AS8: escamas de dragão
N9: CORTINA | AS9: regeneração draconica
B10: DESCRIÇÃO DA TÉCNICA | N10: COBRIR-SE | AS10: Alma Flamejante | BB10: TIPO DE EXPANSÃO
N11: CESTA OCA DE VIME
BB12: DESCRIÇÃO DA EXPANSÃO
B16: PERFIL AMALDIÇOADO
B18: FEITIÇOS CONHECIDOS | G18: 4 | AA18: FEITIÇOS NÍVEL 3 | AJ18: FEITIÇOS NÍVEL 4 | AS18: FEITIÇOS NÍVEL 5
BB19: TÉCNICA MÁXIMA
B20: ATRIBUTO PRINCIPAL | G20: Presença
BB21: NOME DA TÉCNICA
B22: CD Técnica | H22: CD Amaldiçoada
C23: Total | I23: Total
C24: =10+SWITCH(E28, "F", For, "D", Des, "C", Con, "I", Int, "S", Sab, "P", Pre, 0)+E29+E30+'Ficha Pessoal'!BH3 -> 19 | I24: =10+SWITCH(K28, "F", For, "D", Des, "C", Con, "I", Int, "S", Sab, "P", Pre, 0)+K29+K30+'Ficha Pessoal'!BH3 -> 19 | BB24: DESCRIÇÃO DA TÉCNICA MÁXIMA
C28: Atributo | E28: P | I28: Atributo | K28: P
C29: Nível/2 | E29: =ROUNDDOWN('Ficha Pessoal'!BD3/2,0) -> 2 | I29: Nível/2 | K29: =ROUNDDOWN('Ficha Pessoal'!BD3/2,0) -> 2
C30: Outros | E30: 0 | I30: Outros | K30: 0 | AA30: NÍVEIS DE APTIDÃO
AB32: 0 | AG32: 1 | AL32: 1 | AQ32: 0 | AV32: 0
AB35: Aptidão em Aura | AG35: Aptidão em Controle e Leitura | AL35: Aptidão em Barreira | AQ35: Aptidão em Domínio | AV35: Aptidão em Energia Reversa

Sheet Invocações
B2: INVOCAÇÕES
B5: Dragão vermelho | Q5: Dragão branco | AF5: Dragão Marrom | AU5: Invocação 4
C7: Grau da Invocação | R7: Grau da Invocação | AG7: Grau da Invocação | AV7: Grau da Invocação
C8: Terceiro Grau | R8: Terceiro Grau | AG8: Terceiro Grau
C10: 49 | F10: 49 | I10: 18 | L10: 9m | R10: 49 | U10: 49 | X10: 17 | AA10: 9m | AG10: 65 | AJ10: 65 | AM10: 19 | AP10: 9m
C14: ATUAIS | F14: MÁXIMOS | I14: DEFESA | L14: DESLOC. | R14: ATUAIS | U14: MÁXIMOS | X14: DEFESA | AA14: DESLOC. | AG14: ATUAIS | AJ14: MÁXIMOS | AM14: DEFESA | AP14: DESLOC. | AV14: ATUAIS | AY14: MÁXIMOS | BB14: DEFESA | BE14: DESLOC.
C15: PONTOS DE VIDA | R15: PONTOS DE VIDA | AG15: PONTOS DE VIDA | AV15: PONTOS DE VIDA
C16: ATRIBUTOS | R16: ATRIBUTOS | AG16: ATRIBUTOS | AV16: ATRIBUTOS
C17: Atributo | G17: Valor | K17: Modificador | R17: Atributo | V17: Valor | Z17: Modificador | AG17: Atributo | AK17: Valor | AO17: Modificador | AV17: Atributo | AZ17: Valor | BD17: Modificador
C18: Força | G18: 8 | K18: =IF(G18>=10,ROUNDDOWN((G18-10)/2,0),ROUNDUP((G18-10)/2,0)) -> -1 | R18: Força | V18: 8 | Z18: =IF(V18>=10,ROUNDDOWN((V18-10)/2,0),ROUNDUP((V18-10)/2,0)) -> -1 | AG18: Força | AK18: 8 | AO18: =IF(AK18>=10,ROUNDDOWN((AK18-10)/2,0),ROUNDUP((AK18-10)/2,0)) -> -1 | AV18: Força | BD18: =IF(AZ18>=10,ROUNDDOWN((AZ18-10)/2,0),ROUNDUP((AZ18-10)/2,0)) -> -5
C19: Destreza | G19: 16 | K19: =IF(G19>=10,ROUNDDOWN((G19-10)/2,0),ROUNDUP((G19-10)/2,0)) -> 3 | R19: Destreza | V19: 15 | Z19: =IF(V19>=10,ROUNDDOWN((V19-10)/2,0),ROUNDUP((V19-10)/2,0)) -> 2 | AG19: Destreza | AK19: 15 | AO19: =IF(AK19>=10,ROUNDDOWN((AK19-10)/2,0),ROUNDUP((AK19-10)/2,0)) -> 2 | AV19: Destreza | BD19: =IF(AZ19>=10,ROUNDDOWN((AZ19-10)/2,0),ROUNDUP((AZ19-10)/2,0)) -> -5
C20: Constituição | G20: 9 | K20: =IF(G20>=10,ROUNDDOWN((G20-10)/2,0),ROUNDUP((G20-10)/2,0)) -> -1 | R20: Constituição | V20: 8 | Z20: =IF(V20>=10,ROUNDDOWN((V20-10)/2,0),ROUNDUP((V20-10)/2,0)) -> -1 | AG20: Constituição | AK20: 20 | AO20: =IF(AK20>=10,ROUNDDOWN((AK20-10)/2,0),ROUNDUP((AK20-10)/2,0)) -> 5 | AV20: Constituição | BD20: =IF(AZ20>=10,ROUNDDOWN((AZ20-10)/2,0),ROUNDUP((AZ20-10)/2,0)) -> -5
C21: Inteligência | G21: 8 | K21: =IF(G21>=10,ROUNDDOWN((G21-10)/2,0),ROUNDUP((G21-10)/2,0)) -> -1 | R21: Inteligência | V21: 20 | Z21: =IF(V21>=10,ROUNDDOWN((V21-10)/2,0),ROUNDUP((V21-10)/2,0)) -> 5 | AG21: Inteligência | AK21: 8 | AO21: =IF(AK21>=10,ROUNDDOWN((AK21-10)/2,0),ROUNDUP((AK21-10)/2,0)) -> -1 | AV21: Inteligência | BD21: =IF(AZ21>=10,ROUNDDOWN((AZ21-10)/2,0),ROUNDUP((AZ21-10)/2,0)) -> -5
C22: Sabedoria | G22: 18 | K22: =IF(G22>=10,ROUNDDOWN((G22-10)/2,0),ROUNDUP((G22-10)/2,0)) -> 4 | R22: Sabedoria | V22: 8 | Z22: =IF(V22>=10,ROUNDDOWN((V22-10)/2,0),ROUNDUP((V22-10)/2,0)) -> -1 | AG22: Sabedoria | AK22: 8 | AO22: =IF(AK22>=10,ROUNDDOWN((AK22-10)/2,0),ROUNDUP((AK22-10)/2,0)) -> -1 | AV22: Sabedoria | BD22: =IF(AZ22>=10,ROUNDDOWN((AZ22-10)/2,0),ROUNDUP((AZ22-10)/2,0)) -> -5
C23: Presença | G23: 8 | K23: =IF(G23>=10,ROUNDDOWN((G23-10)/2,0),ROUNDUP((G23-10)/2,0)) -> -1 | R23: Presença | V23: 8 | Z23: =IF(V23>=10,ROUNDDOWN((V23-10)/2,0),ROUNDUP((V23-10)/2,0)) -> -1 | AG23: Presença | AK23: 8 | AO23: =IF(AK23>=10,ROUNDDOWN((AK23-10)/2,0),ROUNDUP((AK23-10)/2,0)) -> -1 | AV23: Presença | BD23: =IF(AZ23>=10,ROUNDDOWN((AZ23-10)/2,0),ROUNDUP((AZ23-10)/2,0)) -> -5
C24: Ações e Características | R24: Ações e Características | AG24: Ações e Características | AV24: Ações e Características
C25: Cuspir Fogo | R25: cobertura de gelo (SImples) | AG25: Parrudo
C26: Lança-chamas | R26: Cuspir Gelo | AG26: Casca grossa
C27: escamas endurecidas | R27: congelar feridas (complexa)
C28: Mira aperfeiçoada | R28: Quebrar o gelo
C30: Perícias Treinadas | R30: Perícias Treinadas | AG30: Perícias Treinadas | AV30: Perícias Treinadas
C31: Nome | G31: Atributo | J31: Outros | L31: Bônus | R31: Nome | V31: Atributo | Y31: Outros | AA31: Bônus | AG31: Nome | AK31: Atributo | AN31: Outros | AP31: Bônus | AV31: Nome | AZ31: Atributo | BC31: Outros | BE31: Bônus
C32: a distancia | G32: des | J32: 3 | L32: 6 | R32: a distancia | V32: des | Y32: 3 | AA32: 8 | AG32: corpo a corpo | AK32: for | AN32: 3 | AP32: 5
C33: reflexos | G33: des | J33: 3 | L33: 6 | R33: astucia | V33: sab | Y33: 3 | AA33: 5 | AG33: fortitude | AK33: con | AN33: 3 | AP33: 11
C34: acrobacia | G34: des | J34: 3 | L34: 6 | R34: investigação | V34: int | Y34: 3 | AA34: 11 | AG34: intimidação | AK34: pre | AN34: 3 | AP34: 5
C35: percepção | G35: sab | J35: 3 | L35: 7 | R35: feitiçaria | V35: int | Y35: 3 | AA35: 11 | AG35: sobrevivencia | AK35: sab | AN35: 3 | AP35: 5
C36: intuição | G36: sab | J36: 3 | L36: 7 | R36: historia | V36: int | Y36: 3 | AA36: 11 | AG36: percepção | AK36: sab | AN36: 3 | AP36: 5
B45: Invocação 5 | Q45: Invocação 6 | AF45: Invocação 7 | AU45: Invocação 8
C47: Grau da Invocação | R47: Grau da Invocação | AG47: Grau da Invocação | AV47: Grau da Invocação
C54: ATUAIS | F54: MÁXIMOS | I54: DEFESA | L54: DESLOC. | R54: ATUAIS | U54: MÁXIMOS | X54: DEFESA | AA54: DESLOC. | AG54: ATUAIS | AJ54: MÁXIMOS | AM54: DEFESA | AP54: DESLOC. | AV54: ATUAIS | AY54: MÁXIMOS | BB54: DEFESA | BE54: DESLOC.
C55: PONTOS DE VIDA | R55: PONTOS DE VIDA | AG55: PONTOS DE VIDA | AV55: PONTOS DE VIDA
C56: ATRIBUTOS | R56: ATRIBUTOS | AG56: ATRIBUTOS | AV56: ATRIBUTOS
C57: Atributo | G57: Valor | K57: Modificador | R57: Atributo | V57: Valor | Z57: Modificador | AG57: Atributo | AK57: Valor | AO57: Modificador | AV57: Atributo | AZ57: Valor | BD57: Modificador
C58: Força | K58: =IF(G58>=10,ROUNDDOWN((G58-10)/2,0),ROUNDUP((G58-10)/2,0)) -> -5 | R58: Força | Z58: =IF(V58>=10,ROUNDDOWN((V58-10)/2,0),ROUNDUP((V58-10)/2,0)) -> -5 | AG58: Força | AO58: =IF(AK58>=10,ROUNDDOWN((AK58-10)/2,0),ROUNDUP((AK58-10)/2,0)) -> -5 | AV58: Força | BD58: =IF(AZ58>=10,ROUNDDOWN((AZ58-10)/2,0),ROUNDUP((AZ58-10)/2,0)) -> -5
C59: Destreza | K59: =IF(G59>=10,ROUNDDOWN((G59-10)/2,0),ROUNDUP((G59-10)/2,0)) -> -5 | R59: Destreza | Z59: =IF(V59>=10,ROUNDDOWN((V59-10)/2,0),ROUNDUP((V59-10)/2,0)) -> -5 | AG59: Destreza | AO59: =IF(AK59>=10,ROUNDDOWN((AK59-10)/2,0),ROUNDUP((AK59-10)/2,0)) -> -5 | AV59: Destreza | BD59: =IF(AZ59>=10,ROUNDDOWN((AZ59-10)/2,0),ROUNDUP((AZ59-10)/2,0)) -> -5
C60: Constituição | K60: =IF(G60>=10,ROUNDDOWN((G60-10)/2,0),ROUNDUP((G60-10)/2,0)) -> -5 | R60: Constituição | Z60: =IF(V60>=10,ROUNDDOWN((V60-10)/2,0),ROUNDUP((V60-10)/2,0)) -> -5 | AG60: Constituição | AO60: =IF(AK60>=10,ROUNDDOWN((AK60-10)/2,0),ROUNDUP((AK60-10)/2,0)) -> -5 | AV60: Constituição | BD60: =IF(AZ60>=10,ROUNDDOWN((AZ60-10)/2,0),ROUNDUP((AZ60-10)/2,0)) -> -5
C61: Inteligência | K61: =IF(G61>=10,ROUNDDOWN((G61-10)/2,0),ROUNDUP((G61-10)/2,0)) -> -5 | R61: Inteligência | Z61: =IF(V61>=10,ROUNDDOWN((V61-10)/2,0),ROUNDUP((V61-10)/2,0)) -> -5 | AG61: Inteligência | AO61: =IF(AK61>=10,ROUNDDOWN((AK61-10)/2,0),ROUNDUP((AK61-10)/2,0)) -> -5 | AV61: Inteligência | BD61: =IF(AZ61>=10,ROUNDDOWN((AZ61-10)/2,0),ROUNDUP((AZ61-10)/2,0)) -> -5
C62: Sabedoria | K62: =IF(G62>=10,ROUNDDOWN((G62-10)/2,0),ROUNDUP((G62-10)/2,0)) -> -5 | R62: Sabedoria | Z62: =IF(V62>=10,ROUNDDOWN((V62-10)/2,0),ROUNDUP((V62-10)/2,0)) -> -5 | AG62: Sabedoria | AO62: =IF(AK62>=10,ROUNDDOWN((AK62-10)/2,0),ROUNDUP((AK62-10)/2,0)) -> -5 | AV62: Sabedoria | BD62: =IF(AZ62>=10,ROUNDDOWN((AZ62-10)/2,0),ROUNDUP((AZ62-10)/2,0)) -> -5
C63: Presença | K63: =IF(G63>=10,ROUNDDOWN((G63-10)/2,0),ROUNDUP((G63-10)/2,0)) -> -5 | R63: Presença | Z63: =IF(V63>=10,ROUNDDOWN((V63-10)/2,0),ROUNDUP((V63-10)/2,0)) -> -5 | AG63: Presença | AO63: =IF(AK63>=10,ROUNDDOWN((AK63-10)/2,0),ROUNDUP((AK63-10)/2,0)) -> -5 | AV63: Presença | BD63: =IF(AZ63>=10,ROUNDDOWN((AZ63-10)/2,0),ROUNDUP((AZ63-10)/2,0)) -> -5
C64: Ações e Características | R64: Ações e Características | AG64: Ações e Características | AV64: Ações e Características
...

Sheet Treinamentos
B2: TREINAMENTOS
C4: Treino de Agilidade | L4: Treino de Barreiras | U4: Treino de Compreensão | AD4: Controle de Energia | AM4: Treino de Domínios | AV4: Energia Reversa
C5: 1° Etapa | I5: FALSE | L5: 1° Etapa | R5: FALSE | U5: 1° Etapa | AA5: FALSE | AD5: 1° Etapa | AJ5: FALSE | AM5: 1° Etapa | AS5: FALSE | AV5: 1° Etapa | BB5: FALSE
C6: 2° Etapa | I6: FALSE | L6: 2° Etapa | R6: FALSE | U6: 2° Etapa | AA6: FALSE | AD6: 2° Etapa | AJ6: FALSE | AM6: 2° Etapa | AS6: FALSE | AV6: 2° Etapa | BB6: FALSE
C7: 3° Etapa | I7: FALSE | L7: 3° Etapa | R7: FALSE | U7: 3° Etapa | AA7: FALSE | AD7: 3° Etapa | AJ7: FALSE | AM7: 3° Etapa | AS7: FALSE | AV7: 3° Etapa | BB7: FALSE
C8: 4° Etapa | I8: FALSE | L8: 4° Etapa | R8: FALSE | U8: 4° Etapa | AA8: FALSE | AD8: 4° Etapa | AJ8: FALSE | AM8: 4° Etapa | AS8: FALSE | AV8: 4° Etapa | BB8: FALSE
C9: Treinamento Completo | L9: Treinamento Completo | U9: Treinamento Completo | AD9: Treinamento Completo | AM9: Treinamento Completo | AV9: Treinamento Completo
C10: Com grande velocidade e agilidade, você se torna rápido e capaz de um nível superior de mobilidade e esquivas. Sua margem necessária para conseguir um sucesso crítico em um TR de Reflexos reduz em 2. Seu Deslocamento aumenta em 4,5 metros. | L10: Toda parede que você criar com Técnicas de Barreira recebe RD igual ao seu Nível de Aptidão em Barreiras. | U10: Você chega muito perto de compreender profundamente a energia amaldiçoada, tornando-se familiar com ela e entendendo melhor uma parte dela. Você aumenta um nível de aptidão a sua escolha em 1. | AD10: Em uma situação de combate, imerso no fervor da batalha, você consegue gerar energia: durante uma cena de combate, no começo de toda rodada, você ganha PE Temporário igual a metade do seu bônus de maestria. | AM10: Você se torna um mestre das expansões, entendo o como conseguir a moldar perfeitamente diante a sua vontade e necessidade do momento. Você recebe a aptidão amaldiçoada Modificação Completa. | AV10: Você pode usar a aptidão amaldiçoada Regeneração Aprimorada para curar sua exaustão de técnica após usar expansão de domínio, reduzindo em um turno para 2 pontos de energia reversa gastos.
C16: Treino de Luta | L16: Manejo de Arma | U16: Treino de Perícia | AD16: Potencial Físico | AM16: Treino de Resistência
C17: 1° Etapa | I17: FALSE | L17: 1° Etapa | R17: FALSE | U17: 1° Etapa | AA17: FALSE | AD17: 1° Etapa | AJ17: FALSE | AM17: 1° Etapa | AS17: FALSE
C18: 2° Etapa | I18: FALSE | L18: 2° Etapa | R18: FALSE | U18: 2° Etapa | AA18: FALSE | AD18: 2° Etapa | AJ18: FALSE | AM18: 2° Etapa | AS18: FALSE
C19: 3° Etapa | I19: FALSE | L19: 3° Etapa | R19: FALSE | U19: 3° Etapa | AA19: FALSE | AD19: 3° Etapa | AJ19: FALSE | AM19: 3° Etapa | AS19: FALSE
C20: 4° Etapa | I20: FALSE | L20: 4° Etapa | R20: FALSE | U20: 4° Etapa | AA20: FALSE | AD20: 4° Etapa | AJ20: FALSE | AM20: 4° Etapa | AS20: FALSE
C21: Treinamento Completo | L21: Treinamento Completo | U21: Treinamento Completo | AD21: Treinamento Completo | AM21: Treinamento Completo
C22: Você recebe acesso ao efeito de crítico de ataques desarmados (pugilato). Além disso, você pode, uma vez por rodada, escolher realizar uma rolagem de Luta com vantagem, seja ela para um ataque ou para uma manobra. | L22: Enquanto estiver manejando a arma escolhida, ela recebe uma propriedade de ferramenta amaldiçoada adicional. | U22: Caso realize um teste da perícia escolhida e obtenha um resultado menor do que 5 no d20, você pode o rolar novamente e manter o melhor resultado. | AD22: Durante uma cena de combate, no começo de toda rodada, você recupera uma quantidade de pontos de vigor igual a metade do seu bônus de maestria. | AM22: Sua margem necessária para conseguir um sucesso crítico em um TR de Fortitude reduz em 2. Uma vez por cena, você ignora a primeira falha em testes de morte. Seus pontos de vida máximos aumentam em mais 10.
